<?xml version="1.0"?>
<robot name="rover" xmlns:xacro="http://www.ros.org/wiki/xacro">
    <xacro:include filename="$(find bring_up)/URDF/QT1.gazebo"/>
    <xacro:include filename="$(find bring_up)/URDF/macros.xacro"/>
    <xacro:include filename="lidar.xacro"/>
    
    <xacro:property name="base_width" value="0.7038"/>
    <xacro:property name="base_depth" value="0.3019"/>
    <xacro:property name="base_height" value="0.2"/>
    <xacro:property name="base_mass" value="35.689"/>
    <xacro:property name="wheel_radius" value="0.165"/>
    <xacro:property name="wheel_width" value="0.18"/>
    <xacro:property name="wheel_mass" value="2.2"/>
    <xacro:property name="PI_2" value="1.570796327"/>
    <xacro:property name="PI" value="3.14159265359"/>

    <link name="base_link">
        <pose>0 0 0 0 0 0</pose>
        <inertial>
            <mass value="${base_mass}"/>
            <origin rpy="0 0 0" xyz="0 0 0.085"/>
            <xacro:box_inertia m="${base_mass}" x="${base_depth}" y="${base_width}" z="${base_height}"/>
          </inertial>
        <visual>
            <geometry>
        	<mesh
            filename="package://bring_up/meshes/Chasis.STL" scale="0.001 0.001 .001" />
            </geometry>
            <origin rpy="${PI_2} 0 ${PI_2} " xyz="-.365 -.175 0.262"/>
        </visual>
       <collision>
          <geometry>
        	<mesh
            filename="package://bring_up/meshes/Chasis.STL" scale="0.001 0.001 .001" />
          </geometry>
          <origin rpy="${PI_2} 0 ${PI_2} " xyz="-.365 -.175 0.262"/>
       </collision>
    </link>

    <!-- Definimos las dimensiones de la camara-->
    <link name="ZED_link">
        <inertial>
            <mass value="0.0"/>
            <origin xyz="0.0 0.0 0.0" rpy="0.0 0.0 0.0"/>
            <inertia ixx="0.0" ixy="0.0" ixz="0.0" iyy="0.0" iyz="0.0" izz="0.0"/>
        </inertial>
        <collision>
            <geometry>
                <box size="0.0431 0.17525 0.0325"/>
            </geometry>
            <origin xyz="0.0 0.0 0.0" rpy="0.0 0.0 0.0"/>
        </collision>
        <visual>
            <geometry>
                <box size="0.0431 0.17525 0.0325"/>
            </geometry>
            <origin xyz="0.0 0.0 0.0" rpy="0.0 0.0 0.0"/>
        </visual>
    </link>

    <joint name="base_to_ZED" type="fixed">
        <parent link="base_link"/>
        <child link="ZED_link"/>
        <origin xyz="0.4 0.0 0.38" rpy="0 0 0"/>
    </joint>

    <joint name="ZED_depth_joint" type="fixed">
        <origin xyz="0 0 0" rpy="${-PI/2} 0 ${-PI/2} "/>
        <parent link="ZED_link"/>
        <child link="ZED_depth_link"/>
      </joint>
    
      <link name="ZED_depth_link"></link>

    <!--LLANTA IZQUIERDA FRONT-->
    <link name="flwheel_link">
        <inertial>
            <mass value="${wheel_mass}"/>
            <origin rpy="0 ${PI_2} ${PI_2}" xyz="0 0 0"/>
            <xacro:cylinder_inertia m="${wheel_mass}" r="${wheel_radius}" h="${wheel_width}"/>
          </inertial>
        <visual name="link_flwheel_visual">
            <geometry>
          <mesh
           filename="package://bring_up/meshes/wheel_left_f.STL" />
            </geometry>
            <origin xyz="0.034 -0.013 0" rpy="0 0 0"/>
        </visual>
        <collision name="link_flwheel_collision">
            <geometry>
          <mesh
           filename="package://bring_up/meshes/wheel_left_f.STL" />
            </geometry>
            <origin xyz="0.034 -0.013 0" rpy="0 0 0"/>
        </collision>
    </link>

    <joint name="base_to_flwheel" type="continuous">
        <parent link="base_link"/>
        <child link="flwheel_link"/>
        <origin rpy="${PI_2} 0 0" xyz="0.386 0.375 0"/>
        <axis rpy="0 0 0" xyz="0 0 -1"/>
        <limit effort="10000" velocity="1000"/> 
        <joint_properties damping="1.0" friction="100.0"/>
    </joint>

    <!--LLANTA IZQUIERDA BACK-->
    <link name="blwheel_link">
        <inertial>
            <mass value="${wheel_mass}"/>
            <origin rpy="0  ${PI_2} ${PI_2}" xyz="0 0 0"/>
            <xacro:cylinder_inertia m="${wheel_mass}" r="${wheel_radius}" h="${wheel_width}"/>
          </inertial>
        <visual name="link_blwheel_visual">
            <geometry>
              <mesh
               filename="package://bring_up/meshes/wheel_left_f.STL" />
            </geometry>
            <origin xyz="0.034 -0.013 0" rpy="0 0 0"/>
        </visual>
        <collision name="link_blwheel_collision">
            <geometry>
              <mesh
               filename="package://bring_up/meshes/wheel_left_f.STL" />
            </geometry>
            <origin xyz="0.034 -0.013 0" rpy="0 0 0"/>
        </collision>
    </link>

    <joint name="base_to_alwheel" type="continuous">
        <parent link="base_link"/>
        <child link="blwheel_link"/>
        <origin rpy="${PI_2} 0 0" xyz="-0.45 0.375 0"/>
        <axis rpy="0 0 0" xyz="0 0 -1"/>
        <limit effort="10000" velocity="1000"/>
        <joint_properties damping="1.0" friction="100.0"/>
    </joint>
    
    <!--LLANTA IZQUIERDA ENMEDIO-->
    <link name="middle_wheel">
        <inertial>
            <mass value="${wheel_mass}"/>
            <origin rpy="0 ${PI_2} ${PI_2}" xyz="0 0 0"/>
            <xacro:cylinder_inertia m="${wheel_mass}" r="${wheel_radius}" h="${wheel_width}"/>
          </inertial>
        <visual name="link_wheel">
            <geometry>
          <mesh
           filename="package://bring_up/meshes/wheel_left_f.STL" />
            </geometry>
            <origin xyz="0.034 -0.013 0" rpy="0 0 0"/>
        </visual>
        <collision name="link_wheel_collision">
            <geometry>
          <mesh
           filename="package://bring_up/meshes/wheel_left_f.STL" />
            </geometry>
            <origin xyz="0.034 -0.013 0" rpy="0 0 0"/>
        </collision>
    </link>

    <joint name="base_to_middle_wheel" type="continuous">
        <parent link="base_link"/>
        <child link="middle_wheel"/>
        <origin rpy="${PI_2} 0 0" xyz="-0.037 0.375 0"/>
        <axis rpy="0 0 0" xyz="0 0 -1"/>
        <limit effort="10000" velocity="1000"/>
        <joint_properties damping="1.0" friction="100.0"/>
    </joint>
    
 <!-- LLANTA DERECHA FRONT-->
    <link name="frwheel_link">
        <inertial>
            <mass value="${wheel_mass}"/>
            <origin rpy="0 ${PI_2} ${PI_2}" xyz="0 0 0"/>
            <xacro:cylinder_inertia m="${wheel_mass}" r="${wheel_radius}" h="${wheel_width}"/>
          </inertial>
        <visual name="link_frwheel_visual">
            <geometry>
                <mesh
                  filename="package://bring_up/meshes/wheel_left_f.STL" />
            </geometry>
            <origin xyz="0.034 -0.013 0" rpy="0 0 0"/>
            <!-- <material name="black">
                <color rgba="0 0 0 1"/>
            </material>-->
        </visual>
        <collision name="link_frwheel_collision">
            <geometry>
                <mesh
                   filename="package://bring_up/meshes/wheel_left_f.STL" />
            </geometry>
            <origin xyz="0.034 -0.013 0" rpy="0 0 0"/>
        </collision>
    </link>

    <joint name="base_to_frwheel" type="continuous">
        <parent link="base_link"/>
        <child link="frwheel_link"/>
        <origin rpy="${PI_2} 0 0" xyz="0.40 -0.352 0"/>
        <axis rpy="0 0 0" xyz="0 0 -1"/>
        <limit effort="10000" velocity="1000"/>
        <joint_properties damping="1.0" friction="100.0"/>
    </joint>

    <!--LLANTA DERECHA ATRAS-->
    <link name="brwheel_link">
        <inertial>
            <mass value="${wheel_mass}"/>
            <origin rpy="0 ${PI_2} ${PI_2}" xyz="0 0 0"/>
            <xacro:cylinder_inertia m="${wheel_mass}" r="${wheel_radius}" h="${wheel_width}"/>
          </inertial>
        <visual name="link_brwheel_visual">
            <geometry>
                <mesh
                   filename="package://bring_up/meshes/wheel_left_f.STL" />
            </geometry>
            <origin xyz="0.034 -0.013 0" rpy="0 0 0"/>
        </visual>
        <collision name="link_brwheel_collision">
            <geometry>
                <mesh
                   filename="package://bring_up/meshes/wheel_left_f.STL" />
            </geometry>
            <origin xyz="0.034 -0.013 0" rpy="0 0 0"/>
        </collision>
    </link>

    <joint name="base_to_arwheel" type="continuous">
        <parent link="base_link"/>
        <child link="brwheel_link"/>
        <origin rpy="${PI_2} 0 0" xyz="-0.45 -0.352 0"/>
        <axis rpy="0 0 0" xyz="0 0 -1"/>
        <limit effort="10000" velocity="1000"/>
        <joint_properties damping="1.0" friction="100.0"/>
    </joint>
    
    <!--LLANTA DERECHA ENMEDIO-->
    <link name="middle_wheel_2">
        <inertial>
            <mass value="${wheel_mass}"/>
            <origin rpy="0 ${PI_2} ${PI_2}" xyz="0 0 0"/>
            <xacro:cylinder_inertia m="${wheel_mass}" r="${wheel_radius}" h="${wheel_width}"/>
          </inertial>
        <visual name="link_wheel_2">
            <geometry>
          <mesh
           filename="package://bring_up/meshes/wheel_left_f.STL" />
            </geometry>
            <origin xyz="0.034 -0.013 0" rpy="0 0 0"/>
        </visual>
        <collision name="link_wheel_collision_2">
            <geometry>
          <mesh
           filename="package://bring_up/meshes/wheel_left_f.STL" />
            </geometry>
            <origin xyz="0.034 -0.013 0" rpy="0 0 0"/>
        </collision>
    </link>

    <joint name="base_to_middle_wheel_2" type="continuous">
        <parent link="base_link"/>
        <child link="middle_wheel_2"/>
        <origin rpy="${PI_2} 0 0" xyz="-0.037 -0.352 0"/>
        <axis rpy="0 0 0" xyz="0 0 -1"/>
        <limit effort="10000" velocity="1000"/>
        <joint_properties damping="1.0" friction="100.0"/>
    </joint>

</robot>