<?xml version="1.0"?>
<robot name="rover" xmlns:xacro="http://www.ros.org/wiki/xacro">
    <xacro:include filename="$(find bring_up)/URDF/QT1.gazebo"/>
    <xacro:include filename="$(find bring_up)/URDF/macros.xacro"/>
    <!-- <xacro:include filename="lidar.xacro"/> -->
    
    <xacro:property name="base_width" value="0.7038"/>
    <xacro:property name="base_depth" value="0.3019"/>
    <xacro:property name="base_height" value="0.2"/>
    <xacro:property name="base_mass" value="35.689"/>
    <xacro:property name="wheel_radius" value="0.165"/>
    <xacro:property name="wheel_width" value="0.18"/>
    <xacro:property name="wheel_mass" value="2.2"/>
    <xacro:property name="PI_2" value="1.570796327"/>
    <xacro:property name="PI" value="3.14159265359"/>

    <link name="base_link">
        <pose>0 0 0 0 0 0</pose>
        <inertial>
            <mass value="${base_mass}"/>
            <origin rpy="0 0 0" xyz="0 0 0.085"/>
            <xacro:box_inertia m="${base_mass}" x="${base_depth}" y="${base_width}" z="${base_height}"/>
          </inertial>
        <visual>
            <geometry>
        	<mesh
            filename="package://bring_up/meshes/Chasis.STL" scale="0.001 0.001 .001" />
            </geometry>
            <origin rpy="${PI_2} 0 ${PI_2} " xyz="-.365 -.175 0.262"/>
        </visual>
       <collision>
          <geometry>
        	<mesh
            filename="package://bring_up/meshes/Chasis.STL" scale="0.001 0.001 .001" />
          </geometry>
          <origin rpy="${PI_2} 0 ${PI_2} " xyz="-.365 -.175 0.262"/>
       </collision>
    </link>
<!--
<link name="base_link">
    <pose>0 0 0 0 0 0</pose>
    <inertial>
        <mass value="${base_mass}"/>
        <origin rpy="0 0 0" xyz="0 0 0"/>
        <xacro:box_inertia m="${base_mass}" x="${base_depth}" y="${base_width}" z="${base_height}"/>
      </inertial>
    <visual>
        <geometry>
            <box size="${base_width} ${base_depth} ${base_height}"/>
        </geometry>
        <origin rpy="0 0 0" xyz="0 0 0"/>
    </visual>
   <collision> 
    <geometry>
        <box size="${base_width} ${base_depth} ${base_height}"/>
    </geometry>
   </collision>
</link>-->
    <!-- Definimos las dimensiones de la camara-->
    <link name="ZED_link">
        <inertial>
            <mass value="0.0"/>
            <origin xyz="0.0 0.0 0.0" rpy="0.0 0.0 0.0"/>
            <inertia ixx="0.0" ixy="0.0" ixz="0.0" iyy="0.0" iyz="0.0" izz="0.0"/>
        </inertial>
        <collision>
            <geometry>
                <box size="0.0431 0.17525 0.0325"/>
            </geometry>
            <origin xyz="0.0 0.0 0.0" rpy="0.0 0.0 0.0"/>
        </collision>
        <visual>
            <geometry>
                <box size="0.0431 0.17525 0.0325"/>
            </geometry>
            <origin xyz="0.0 0.0 0.0" rpy="0.0 0.0 0.0"/>
        </visual>
    </link>

    <joint name="base_to_ZED" type="fixed">
        <parent link="base_link"/>
        <child link="ZED_link"/>
        <origin xyz="0.4 0.0 0.38" rpy="0 0 0"/>
    </joint>

    <joint name="ZED_depth_joint" type="fixed">
        <origin xyz="0 0 0" rpy="${-PI/2} 0 ${-PI/2} "/>
        <parent link="ZED_link"/>
        <child link="ZED_depth_link"/>
      </joint>
    
      <link name="ZED_depth_link"></link>

    <!-- Definimos las dimensiones de la barra diferencial-->
    
<!--
    <link name="Barra_diferencial">
        <inertial>
            <mass value="1"/>
            <origin xyz="0.0 0.0 0.0" rpy="0.0 0.0 0.0"/>
            <inertia ixx="0.0" ixy="0.0" ixz="0.0" iyy="0.0" iyz="0.0" izz="0.0"/>
        </inertial>
        <collision>
            <geometry>
          <mesh
           filename="package://bring_up/meshes/barra_diferencial_link.STL" /> 
            </geometry>
            <origin xyz="0 0 0" rpy="${PI_2} 0.0 0.0"/>
        </collision>
        <visual>
            <geometry>
          <mesh
           filename="package://bring_up/meshes/barra_diferencial_link.STL" />
            </geometry>
            <origin xyz="0 0 0" rpy="${PI_2} 0.0 0.0"/>
        </visual>
    </link>

    <joint name="base_to_barra" type="fixed">
        <parent link="base_link"/>
        <child link="Barra_diferencial"/>
        <origin xyz="-0.315 0 0.389" rpy="0 0 0"/>
    </joint>
-->


    <!-- Definimos las dimensiones de la rotula 1-->
    
<!--    <link name="rotula_1">
        <inertial>
            <mass value="1"/>
            <origin xyz="0.0 0.0 0.0" rpy="0.0 0.0 0.0"/>
            <inertia ixx="0.0" ixy="0.0" ixz="0.0" iyy="0.0" iyz="0.0" izz="0.0"/>
        </inertial>
        <collision>
            <geometry>
          <mesh
           filename="package://bring_up/meshes/rotula_right_link.STL" /> 
            </geometry>
            <origin xyz="0 0 0" rpy="${PI_2} 0.0 0.0"/>
        </collision>
        <visual>
            <geometry>
          <mesh
           filename="package://bring_up/meshes/rotula_right_link.STL" />
            </geometry>
            <origin xyz="0 0 0" rpy="${PI_2} 0.0 0.0"/>
        </visual>
    </link>

    <joint name="base_to_rotula1" type="fixed">
        <parent link="base_link"/>
        <child link="rotula_1"/>
        <origin xyz="-0.381 -0.22 0.0165" rpy="0 0 0"/>
    </joint>
-->


    <!-- Definimos las dimensiones de la rotula 2-->
    
<!--    <link name="rotula_2">
        <inertial>
            <mass value="1"/>
            <origin xyz="0.0 0.0 0.0" rpy="0.0 0.0 0.0"/>
            <inertia ixx="0.0" ixy="0.0" ixz="0.0" iyy="0.0" iyz="0.0" izz="0.0"/>
        </inertial>
        <collision>
            <geometry>
          <mesh
           filename="package://bring_up/meshes/rotula_right_link.STL" /> 
            </geometry>
            <origin xyz="0 0 0" rpy="${PI_2} 0.0 0.0"/>
        </collision>
        <visual>
            <geometry>
          <mesh
           filename="package://bring_up/meshes/rotula_right_link.STL" />
            </geometry>
            <origin xyz="0 0 0" rpy="${PI_2} 0.0 0.0"/>
        </visual>
    </link>

    <joint name="base_to_rotula2" type="fixed">
        <parent link="base_link"/>
        <child link="rotula_2"/>
        <origin xyz="-0.381 0.22 0.0165" rpy="0 0 0"/>
    </joint>
-->





    <!-- TUBITO IZQUIERDA-->
    

<!--    <link name="Tubito_1">
        <inertial>
            <mass value="1"/>
            <origin xyz="0.0 0.0 0.0" rpy="0.0 0.0 0.0"/>
            <inertia ixx="0.0" ixy="0.0" ixz="0.0" iyy="0.0" iyz="0.0" izz="0.0"/>
        </inertial>
        <collision>
            <geometry>
          <mesh
           filename="package://bring_up/meshes/tubito_left.STL" /> 
            </geometry>
            <origin xyz="-0.08 0.46 -0.05" rpy="${PI_2} 0.0 0.0"/>
        </collision>
        <visual>
            <geometry>
          <mesh
           filename="package://bring_up/meshes/tubito_left.STL" />
            </geometry>
            <origin xyz="-0.08 0.46 -0.05" rpy="${PI_2} 0.0 0.0"/>
        </visual>
    </link>

    <joint name="base_to_tubito_1" type="fixed">
        <parent link="base_link"/>
        <child link="Tubito_1"/>
        <origin xyz="-0.035 0.3 0.3115" rpy="0 0 ${PI}"/>
    </joint>
-->

    <!-- TUBITO DERECHA-->

<!--    <link name="Tubito_2">
        <inertial>
            <mass value="1"/>
            <origin xyz="0.0 0.0 0.0" rpy="0.0 0.0 0.0"/>
            <inertia ixx="0.0" ixy="0.0" ixz="0.0" iyy="0.0" iyz="0.0" izz="0.0"/>
        </inertial>
        <collision>
            <geometry>
          <mesh
           filename="package://bring_up/meshes/tubito_left.STL" /> 
            </geometry>
            <origin xyz="-0.08 0.46 -0.05" rpy="${PI_2} 0.0 0.0"/>
        </collision>
        <visual>
            <geometry>
          <mesh
           filename="package://bring_up/meshes/tubito_left.STL" />
            </geometry>
            <origin xyz="-0.08 0.46 -0.05" rpy="${PI_2} 0.0 0.0"/>
        </visual>
    </link>

    <joint name="base_to_tubito_2" type="fixed">
        <parent link="base_link"/>
        <child link="Tubito_2"/>
        <origin xyz="-0.035 -0.3 0.3115" rpy="0 0 0"/>
    </joint>
-->




    <!-- MCLOVIN IZQUIERDA ATRAS-->
    
<!--    <link name="Mclovin_left">
        <inertial>
            <mass value="1"/>
            <origin xyz="0.0 0.0 0.0" rpy="0.0 0.0 0.0"/>
            <inertia ixx="0.0" ixy="0.0" ixz="0.0" iyy="0.0" iyz="0.0" izz="0.0"/>
        </inertial>
        <collision>
            <geometry>
          <mesh
           filename="package://bring_up/meshes/mclovib_rigth_front.STL" /> 
            </geometry>
            <origin xyz="0.08 0.05 -0.03" rpy="0.0 0.0 0.0"/>
        </collision>
        <visual>
            <geometry>
          <mesh
           filename="package://bring_up/meshes/mclovib_rigth_front.STL" />
            </geometry>
            <origin xyz="0.08 0.05 -0.03" rpy="0.0 0.0 0.0"/>
        </visual>
    </link>

    <joint name="base_to_mclovin_left" type="fixed">
        <parent link="Tubito_1"/>
        <child link="Mclovin_left"/>
        <origin xyz="0.0 0.08 0.0" rpy="${PI_2} 0 0"/>
    </joint>
-->


    <!-- MCLOVIN IZQUIERDA FRONT-->
    
<!--    <link name="Mclovin_front">
        <inertial>
            <mass value="1"/>
            <origin xyz="0.0 0.0 0.0" rpy="0.0 0.0 0.0"/>
            <inertia ixx="0.0" ixy="0.0" ixz="0.0" iyy="0.0" iyz="0.0" izz="0.0"/>
        </inertial>
        <collision>
            <geometry>
          <mesh
           filename="package://bring_up/meshes/mclovin_right_b.STL" /> 
            </geometry>
            <origin xyz="0.0 0.0 0.0" rpy="0.0 0.0 0.0"/>
        </collision>
        <visual>
            <geometry>
          <mesh
           filename="package://bring_up/meshes/mclovin_right_b.STL" />
            </geometry>
            <origin xyz="0.0 0.0 0.0" rpy="0.0 0.0 0.0"/>
        </visual>
    </link>

    <joint name="base_to_mclovin_front" type="fixed">
        <parent link="Tubito_1"/>
        <child link="Mclovin_front"/>
        <origin xyz="0.0 0.08 0.005" rpy="${PI_2} 0 0"/>
    </joint>
-->




    <!-- MCLOVIN DERECHA FRONT-->
<!--    <link name="Mclovin_left_2">
        <inertial>
            <mass value="1"/>
            <origin xyz="0.0 0.0 0.0" rpy="0.0 0.0 0.0"/>
            <inertia ixx="0.0" ixy="0.0" ixz="0.0" iyy="0.0" iyz="0.0" izz="0.0"/>
        </inertial>
        <collision>
            <geometry>
          <mesh
           filename="package://bring_up/meshes/mclovib_rigth_front.STL" /> 
            </geometry>
            <origin xyz="0.08 0.05 -0.03" rpy="0.0 0.0 0.0"/>
        </collision>
        <visual>
            <geometry>
          <mesh
           filename="package://bring_up/meshes/mclovib_rigth_front.STL" />
            </geometry>
            <origin xyz="0.08 0.05 -0.03" rpy="0.0 0.0 0.0"/>
        </visual>
    </link>

    <joint name="base_to_mclovin_left_2" type="fixed">
        <parent link="Tubito_2"/>
        <child link="Mclovin_left_2"/>
        <origin xyz="0.0 0.09 0.0" rpy="${PI_2} 0 0"/>
    </joint>
-->


    <!-- MCLOVIN DERECHA ATRAS-->
    
<!--    <link name="Mclovin_front_2">
        <inertial>
            <mass value="1"/>
            <origin xyz="0.0 0.0 0.0" rpy="0.0 0.0 0.0"/>
            <inertia ixx="0.0" ixy="0.0" ixz="0.0" iyy="0.0" iyz="0.0" izz="0.0"/>
        </inertial>
        <collision>
            <geometry>
          <mesh
           filename="package://bring_up/meshes/mclovin_right_b.STL" /> 
            </geometry>
            <origin xyz="0.0 0.0 0.0" rpy="0.0 0.0 0.0"/>
        </collision>
        <visual>
            <geometry>
          <mesh
           filename="package://bring_up/meshes/mclovin_right_b.STL" />
            </geometry>
            <origin xyz="0.0 0.0 0.0" rpy="0.0 0.0 0.0"/>
        </visual>
    </link>

    <joint name="base_to_mclovin_front_2" type="fixed">
        <parent link="Tubito_2"/>
        <child link="Mclovin_front_2"/>
        <origin xyz="0.0 0.09 0.005" rpy="${PI_2} 0 0"/>
    </joint>
-->







    <!-- TUBULAR IZQUIERDA ATRAS-->
    
<!--    <link name="tubular_back">
        <inertial>
            <mass value="1"/>
            <origin xyz="0.0 0.0 0.0" rpy="0.0 0.0 0.0"/>
            <inertia ixx="0.0" ixy="0.0" ixz="0.0" iyy="0.0" iyz="0.0" izz="0.0"/>
        </inertial>
        <collision>
            <geometry>
          <mesh
           filename="package://bring_up/meshes/tubular_left_b.STL" /> 
            </geometry>
            <origin xyz="-0.572 -0.143 0.0" rpy="0.0 0.0 0.0"/>
        </collision>
        <visual>
            <geometry>
          <mesh
           filename="package://bring_up/meshes/tubular_left_b.STL" />
            </geometry>
            <origin xyz="-0.572 -0.143 0.0" rpy="0.0 0.0 0.0"/>
        </visual>
    </link>

    <joint name="mclovin_to_tubular_1" type="fixed">
        <parent link="Mclovin_left"/>
        <child link="tubular_back"/>
        <origin xyz="0.142 -0.142 0.0" rpy="0 0 0"/>
    </joint>
-->


    <!-- TUBULAR DERECHA FRONT-->
    
<!--    <link name="tubular_back_2">
        <inertial>
            <mass value="1"/>
            <origin xyz="0.0 0.0 0.0" rpy="0.0 0.0 0.0"/>
            <inertia ixx="0.0" ixy="0.0" ixz="0.0" iyy="0.0" iyz="0.0" izz="0.0"/>
        </inertial>
        <collision>
            <geometry>
          <mesh
           filename="package://bring_up/meshes/tubular_left_b.STL" /> 
            </geometry>
            <origin xyz="-0.572 -0.143 0.0" rpy="0.0 0.0 0.0"/>
        </collision>
        <visual>
            <geometry>
          <mesh
           filename="package://bring_up/meshes/tubular_left_b.STL" />
            </geometry>
            <origin xyz="-0.572 -0.143 0.0" rpy="0.0 0.0 0.0"/>
        </visual>
    </link>

    <joint name="mclovin_to_tubular_3" type="fixed">
        <parent link="Mclovin_left_2"/>
        <child link="tubular_back_2"/>
        <origin xyz="0.142 -0.139 0.0" rpy="0 0 0"/>
    </joint>
-->

    <!-- TUBULAR IZQUIERDA FRONT-->
    
<!--    <link name="tubular_front">
        <inertial>
            <mass value="1"/>
            <origin xyz="0.0 0.0 0.0" rpy="0.0 0.0 0.0"/>
            <inertia ixx="0.0" ixy="0.0" ixz="0.0" iyy="0.0" iyz="0.0" izz="0.0"/>
        </inertial>
        <collision>
            <geometry>
          <mesh
           filename="package://bring_up/meshes/tubular_left_f.STL" /> 
            </geometry>
            <origin xyz="0.0 0.0 0.0" rpy="0.0 0.0 0.0"/>
        </collision>
        <visual>
            <geometry>
          <mesh
           filename="package://bring_up/meshes/tubular_left_f.STL" />
            </geometry>
            <origin xyz="0.0 0.0 0.0" rpy="0.0 0.0 0.0"/>
        </visual>
    </link>

    <joint name="mclovin_to_tubular_2" type="fixed">
        <parent link="Mclovin_front"/>
        <child link="tubular_front"/>
        <origin xyz="-0.142 -0.142 0.0" rpy="0 0 0"/>
    </joint>
-->


    <!-- TUBULAR DERECHA ATRAS-->
    
<!--    <link name="tubular_front_2">
        <inertial>
            <mass value="1"/>
            <origin xyz="0.0 0.0 0.0" rpy="0.0 0.0 0.0"/>
            <inertia ixx="0.0" ixy="0.0" ixz="0.0" iyy="0.0" iyz="0.0" izz="0.0"/>
        </inertial>
        <collision>
            <geometry>
          <mesh
           filename="package://bring_up/meshes/tubular_left_f.STL" /> 
            </geometry>
            <origin xyz="0.0 0.0 0.0" rpy="0.0 0.0 0.0"/>
        </collision>
        <visual>
            <geometry>
          <mesh
           filename="package://bring_up/meshes/tubular_left_f.STL" />
            </geometry>
            <origin xyz="0.0 0.0 0.0" rpy="0.0 0.0 0.0"/>
        </visual>
    </link>

    <joint name="mclovin_to_tubular_4" type="fixed">
        <parent link="Mclovin_front_2"/>
        <child link="tubular_front_2"/>
        <origin xyz="-0.142 -0.142 0.0" rpy="0 0 0"/>
    </joint>
-->







    <!--LLANTA IZQUIERDA FRONT-->
    <link name="flwheel_link">
        <inertial>
            <mass value="${wheel_mass}"/>
            <origin rpy="0 ${PI_2} ${PI_2}" xyz="0 0 0"/>
            <xacro:cylinder_inertia m="${wheel_mass}" r="${wheel_radius}" h="${wheel_width}"/>
          </inertial>
        <visual name="link_flwheel_visual">
            <geometry>
          <mesh
           filename="package://bring_up/meshes/wheel_left_f.STL" />
            </geometry>
            <origin xyz="0.034 -0.013 0" rpy="0 0 0"/>
            <!-- <material name="black">
                <color rgba="0 0 0 1"/>
            </material>-->
        </visual>
        <collision name="link_flwheel_collision">
            <geometry>
          <mesh
           filename="package://bring_up/meshes/wheel_left_f.STL" />
            </geometry>
            <origin xyz="0.034 -0.013 0" rpy="0 0 0"/>
            <!-- <origin rpy="${PI_2} 0 0" xyz="0.35 0.34095 0"/>-->
            <!-- <material name="black">
                <color rgba="0 0 0 1"/>
            </material>-->
        </collision>
    </link>

    <joint name="base_to_flwheel" type="continuous">
        <parent link="base_link"/>
        <child link="flwheel_link"/>
        <origin rpy="${PI_2} 0 0" xyz="0.386 0.375 0"/>
        <axis rpy="0 0 0" xyz="0 0 -1"/>
        <limit effort="10000" velocity="1000"/> 
        <joint_properties damping="1.0" friction="100.0"/>
    </joint>
    
    


    <!--LLANTA IZQUIERDA BACK-->
    <link name="blwheel_link">
        <inertial>
            <mass value="${wheel_mass}"/>
            <origin rpy="0  ${PI_2} ${PI_2}" xyz="0 0 0"/>
            <xacro:cylinder_inertia m="${wheel_mass}" r="${wheel_radius}" h="${wheel_width}"/>
          </inertial>
        <visual name="link_blwheel_visual">
            <geometry>
              <mesh
               filename="package://bring_up/meshes/wheel_left_f.STL" />
            </geometry>
            <origin xyz="0.034 -0.013 0" rpy="0 0 0"/>
            <!-- <material name="black">
                <color rgba="0 0 0 1"/>
            </material>-->
        </visual>
        <collision name="link_blwheel_collision">
            <geometry>
              <mesh
               filename="package://bring_up/meshes/wheel_left_f.STL" />
            </geometry>
            <origin xyz="0.034 -0.013 0" rpy="0 0 0"/>
            <!-- <origin rpy="${PI_2} 0 0" xyz="-0.35 0.34095 0"/>-->
            <!-- <material name="black">
                <color rgba="0 0 0 1"/>
            </material>-->
        </collision>
    </link>

    <joint name="base_to_alwheel" type="continuous">
        <parent link="base_link"/>
        <child link="blwheel_link"/>
        <origin rpy="${PI_2} 0 0" xyz="-0.45 0.375 0"/>
        <axis rpy="0 0 0" xyz="0 0 -1"/>
        <limit effort="10000" velocity="1000"/>
        <joint_properties damping="1.0" friction="100.0"/>
    </joint>
    
 
 
 

    <!--LLANTA IZQUIERDA ENMEDIO-->
    <link name="middle1_link">
        <inertial>
            <mass value="${wheel_mass}"/>
            <origin rpy="0 ${PI_2} ${PI_2}" xyz="0 0 0"/>
            <xacro:cylinder_inertia m="${wheel_mass}" r="${wheel_radius}" h="${wheel_width}"/>
          </inertial>
        <visual name="link_wheel">
            <geometry>
          <mesh
           filename="package://bring_up/meshes/wheel_left_f.STL" />
            </geometry>
            <origin xyz="0.034 -0.013 0" rpy="0 0 0"/>
            <!-- <material name="black">
                <color rgba="0 0 0 1"/>
            </material>-->
        </visual>
        <collision name="link_wheel_collision">
            <geometry>
          <mesh
           filename="package://bring_up/meshes/wheel_left_f.STL" />
            </geometry>
            <origin xyz="0.034 -0.013 0" rpy="0 0 0"/>
            <!-- <origin rpy="${PI_2} 0 0" xyz="0.35 0.34095 0"/>-->
            <!-- <material name="black">
                <color rgba="0 0 0 1"/>
            </material>-->
        </collision>
    </link>

    <joint name="base_to_middle1_link" type="continuous">
        <parent link="base_link"/>
        <child link="middle1_link"/>
        <origin rpy="${PI_2} 0 0" xyz="-0.037 0.375 0"/>
        <axis rpy="0 0 0" xyz="0 0 -1"/>
        <limit effort="10000" velocity="1000"/>
        <joint_properties damping="1.0" friction="100.0"/>
    </joint>
    
    
 
    

 <!-- LLANTA DERECHA FRONT-->
    <link name="frwheel_link">
        <inertial>
            <mass value="${wheel_mass}"/>
            <origin rpy="0 ${PI_2} ${PI_2}" xyz="0 0 0"/>
            <xacro:cylinder_inertia m="${wheel_mass}" r="${wheel_radius}" h="${wheel_width}"/>
          </inertial>
        <visual name="link_frwheel_visual">
            <geometry>
                <mesh
                  filename="package://bring_up/meshes/wheel_left_f.STL" />
            </geometry>
            <origin xyz="0.034 -0.013 0" rpy="0 0 0"/>
            <!-- <material name="black">
                <color rgba="0 0 0 1"/>
            </material>-->
        </visual>
        <collision name="link_frwheel_collision">
            <geometry>
                <mesh
                   filename="package://bring_up/meshes/wheel_left_f.STL" />
            </geometry>
            <origin xyz="0.034 -0.013 0" rpy="0 0 0"/>
            <!-- <origin rpy="${PI_2} 0 0" xyz="0.35 -0.34095 0"/>-->
            <!-- <material name="black">
                <color rgba="0 0 0 1"/>
            </material>-->
        </collision>
    </link>

    <joint name="base_to_frwheel" type="continuous">
        <parent link="base_link"/>
        <child link="frwheel_link"/>
        <origin rpy="${PI_2} 0 0" xyz="0.40 -0.352 0"/>
        <axis rpy="0 0 0" xyz="0 0 -1"/>
        <limit effort="10000" velocity="1000"/>
        <joint_properties damping="1.0" friction="100.0"/>
    </joint>



    <!--LLANTA DERECHA ATRAS-->
    <link name="brwheel_link">
        <inertial>
            <mass value="${wheel_mass}"/>
            <origin rpy="0 ${PI_2} ${PI_2}" xyz="0 0 0"/>
            <xacro:cylinder_inertia m="${wheel_mass}" r="${wheel_radius}" h="${wheel_width}"/>
          </inertial>
        <visual name="link_brwheel_visual">
            <geometry>
                <mesh
                   filename="package://bring_up/meshes/wheel_left_f.STL" />
            </geometry>
            <origin xyz="0.034 -0.013 0" rpy="0 0 0"/>
            <!-- <material name="black">
                <color rgba="0 0 0 1"/>
            </material>-->
        </visual>
        <collision name="link_brwheel_collision">
            <geometry>
                <mesh
                   filename="package://bring_up/meshes/wheel_left_f.STL" />
            </geometry>
            <origin xyz="0.034 -0.013 0" rpy="0 0 0"/>
            <!-- <origin rpy="${PI_2} 0 0" xyz="-0.35 -0.34095 0"/>-->
            <!-- <material name="black">
                <color rgba="0 0 0 1"/>
            </material>-->
        </collision>
    </link>

    <joint name="base_to_arwheel" type="continuous">
        <parent link="base_link"/>
        <child link="brwheel_link"/>
        <origin rpy="${PI_2} 0 0" xyz="-0.45 -0.352 0"/>
        <axis rpy="0 0 0" xyz="0 0 -1"/>
        <limit effort="10000" velocity="1000"/>
        <joint_properties damping="1.0" friction="100.0"/>
    </joint>
    

    <!--LLANTA DERECHA ENMEDIO-->
    <link name="middle2_link">
        <inertial>
            <mass value="${wheel_mass}"/>
            <origin rpy="0 ${PI_2} ${PI_2}" xyz="0 0 0"/>
            <xacro:cylinder_inertia m="${wheel_mass}" r="${wheel_radius}" h="${wheel_width}"/>
          </inertial>
        <visual name="link_wheel_2">
            <geometry>
          <mesh
           filename="package://bring_up/meshes/wheel_left_f.STL" />
            </geometry>
            <origin xyz="0.034 -0.013 0" rpy="0 0 0"/>
            <!-- <material name="black">
                <color rgba="0 0 0 1"/>
            </material>-->
        </visual>
        <collision name="link_wheel_collision_2">
            <geometry>
          <mesh
           filename="package://bring_up/meshes/wheel_left_f.STL" />
            </geometry>
            <origin xyz="0.034 -0.013 0" rpy="0 0 0"/>
            <!-- <origin rpy="${PI_2} 0 0" xyz="0.35 0.34095 0"/>-->
            <!-- <material name="black">
                <color rgba="0 0 0 1"/>
            </material>-->
        </collision>
    </link>

    <joint name="base_to_middle2_link" type="continuous">
        <parent link="base_link"/>
        <child link="middle2_link"/>
        <origin rpy="${PI_2} 0 0" xyz="-0.037 -0.352 0"/>
        <axis rpy="0 0 0" xyz="0 0 -1"/>
        <limit effort="10000" velocity="1000"/>
        <joint_properties damping="1.0" friction="100.0"/>
    </joint>

    
 
    



</robot>
<!-- rosrun rqt_robot_steering rqt_robot_steering-->
